Workbook

Sheet Feuille
B1: Cachet de l'etablissement
D2: FEUILLE DE CONSOMMATION JOURNALIERE | J2: Office National des Oeuvres Universitaires
J3: Direction des Oeuvres Universitaires
J4: Résidence Universitaire : 500 Lits
C6: Journée du | D6: 46174 | J6: brarhi abdelhak restau central
A7: NATURE DES DENREES | C7: Stock magasin | D7: Entrées Du Jour | F7: Total du | G7: Sorties Du Jour | J7: Restes du | K7: OBSERVATIONS | L7: EFFECTIF DE LA JOURNEE
A8: DE CONSOMMATION | C8: de la veille | D8: Quantités | E8: P.U | F8: Magasin | G8: Quantités | H8: P.U | I8: Valeur des sorties de la jourée | J8: Quantités
A9: 1 | B9: خبز محسن 250 غ | C9: ='شهر ماي'!J2054 | D9: 100 | E9: 8 | F9: =C9+D9 -> 100 | G9: 100 | H9: =E9 -> 8 | I9: =G9*H9 -> 800 | J9: =F9-G9 | M9: Petit | N9: Déjenuer | O9: Diner
A10: 2 | B10: هلالـــيات | C10: ='شهر ماي'!J2055 | E10: 30 | F10: =C10+D10 | H10: =E10 -> 30 | I10: =G10*H10 | J10: =F10-G10 | M10: Déjenuer
A11: 3 | B11: حليب بودرة جاف | C11: ='شهر ماي'!J2056 | E11: 1100 | F11: =C11+D11 | H11: =E11 -> 1100 | I11: =G11*H11 | J11: =F11-G11 | L11: Pensio- | M11: 0 | N11: 111 | O11: 0
A12: 4 | B12: ســـــــكــر | C12: ='شهر ماي'!J2057 | E12: 90 | F12: =C12+D12 | H12: =E12 -> 90 | I12: =G12*H12 | J12: =F12-G12 | L12: nnaires
A13: 5 | B13: قهـــــــــوة | C13: ='شهر ماي'!J2058 | E13: 1000 | F13: =C13+D13 | H13: =E13 -> 1000 | I13: =G13*H13 | J13: =F13-G13 | L13: Agents | M13: 0 | N13: 0 | O13: 0
A14: 6 | B14: مربى | C14: ='شهر ماي'!J2059 | E14: 273.7 | F14: =C14+D14 | H14: =E14 -> 273.7 | I14: =G14*H14 | J14: =F14-G14 | L14: Invités
A15: 7 | B15: ميلفاي | C15: ='شهر ماي'!J2060 | E15: 40 | F15: =C15+D15 | H15: =E15 -> 40 | I15: =G15*H15 | J15: =F15-G15 | L15: TOTAUX | M15: =SUM(M10:M14) | N15: =N11 -> 111 | O15: =O11+O13
A16: 8 | B16: كروكـــــــــــــي | C16: ='شهر ماي'!J2061 | E16: 30 | F16: =C16+D16 | H16: =E16 -> 30 | I16: =G16*H16 | J16: =F16-G16
A17: 9 | B17: خبز بالشكولاطة | C17: ='شهر ماي'!J2062 | E17: 30 | F17: =C17+D17 | H17: =E17 -> 30 | I17: =G17*H17 | J17: =F17-G17
A18: 10 | B18: مــــــادلان | C18: ='شهر ماي'!J2063 | E18: 60 | F18: =C18+D18 | H18: =E18 -> 60 | I18: =G18*H18 | J18: =F18-G18 | L18: (1) Moyenne des | N18: =SUM(N11) -> 111
A19: 11 | B19: لحـــم العـــــجل | C19: ='شهر ماي'!J2064 | E19: 1559 | F19: =C19+D19 | H19: =E19 -> 1559 | I19: =G19*H19 | J19: =F19-G19 | L19: Personnes nourries
A20: 12 | B20: لحم الخروف | C20: ='شهر ماي'!J2065 | E20: 2295 | F20: =C20+D20 | H20: =E20 -> 2295 | I20: =G20*H20 | J20: =F20-G20
A21: 14 | B21: دجــــــاج طازج | C21: ='شهر ماي'!J2066 | E21: 450 | F21: =C21+D21 | H21: =E21 -> 450 | I21: 0 | J21: =F21-G21
A22: 13 | B22: Lait en boit 1 L | C22: ='شهر ماي'!J2067 | E22: 120 | F22: =C22+D22 | H22: =E22 -> 120 | I22: =G22*H22 | J22: =F22-G22 | M22: Menu
A23: 14 | B23: fromage ميزان | C23: ='شهر ماي'!J2068 | E23: 571.2 | F23: =C23+D23 | H23: =E23 -> 571.2 | I23: =G23*H23 | J23: =F23-G23
A24: 15 | B24: سمك سردين | C24: ='شهر ماي'!J2069 | E24: 1356.6 | F24: =C24+D24 | H24: =E24 -> 1356.6 | I24: =G24*H24 | J24: =F24-G24 | M24: Petit Déjenue
A25: 16 | B25: زلابية | C25: ='شهر ماي'!J2070 | E25: 430 | F25: =C25+D25 | H25: =E25 -> 430 | I25: =G25*H25 | J25: =F25-G25
A26: 17 | B26: قلب اللوز | C26: ='شهر ماي'!J2071 | E26: 45 | F26: =C26+D26 | H26: =E26 -> 45 | I26: =G26*H26 | J26: =F26-G26
A27: 18 | B27: بطاطا مسحوقة | C27: ='شهر ماي'!J2072 | E27: 1142.4 | F27: =C27+D27 | H27: =E27 -> 1142.4 | I27: =G27*H27 | J27: =F27-G27
A28: 19 | B28: فطر معلب | C28: ='شهر ماي'!J2073 | E28: 1142.4 | F28: =C28+D28 | H28: =E28 -> 1142.4 | I28: =G28*H28 | J28: =F28-G28
A29: 20 | B29: بيـــــــــض | C29: ='شهر ماي'!J2074 -> 1418 | E29: 16 | F29: =C29+D29 -> 1418 | H29: =E29 -> 16 | I29: =G29*H29 | J29: =F29-G29 -> 1418
A30: 21 | B30: جبـــــــــن 1/16 | C30: ='شهر ماي'!J2075 -> 444 | E30: 218.96 | F30: =C30+D30 -> 444 | G30: 14 | H30: =E30 -> 218.96 | I30: =G30*H30 -> 3065.44 | J30: =F30-G30 -> 430
A31: 22 | B31: ورق المنيوم | C31: ='شهر ماي'!J2076 | E31: 2975 | F31: =C31+D31 | H31: =E31 -> 2975 | I31: =G31*H31 | J31: =F31-G31
A32: 23 | B32: لبن 1 ليتر | C32: ='شهر ماي'!J2077 | E32: 74.38 | F32: =C32+D32 | H32: =E32 -> 74.38 | I32: =G32*H32 | J32: =F32-G32
A33: 24 | B33: جبن صلب لتبشير | C33: ='شهر ماي'!J2078 | E33: 1190 | F33: =C33+D33 | H33: =E33 -> 1190 | I33: =G33*H33 | J33: =F33-G33
A34: 25 | B34: زيــــــــــــــــت | C34: ='شهر ماي'!J2079 -> 13.8 | E34: 600 | F34: =C34+D34 -> 13.8 | G34: 0.2 | H34: =E34 -> 600 | I34: =G34*H34 -> 120 | J34: =F34-G34 -> 13.6
A35: 26 | B35: خـــــــــــــــل | C35: ='شهر ماي'!J2080 -> 80 | E35: 119 | F35: =C35+D35 -> 80 | G35: 1 | H35: =E35 -> 119 | I35: =G35*H35 -> 119 | J35: =F35-G35 -> 79 | M35: Déjenue
A36: 27 | B36: ملح المائدة | C36: ='شهر ماي'!J2081 -> 64 | E36: 47.6 | F36: =C36+D36 -> 64 | G36: 1 | H36: =E36 -> 47.6 | I36: =G36*H36 -> 47.6 | J36: =F36-G36 -> 63
A37: 28 | B37: طماطم 4/4 | C37: ='شهر ماي'!J2082 -> 172 | E37: 357 | F37: =C37+D37 -> 172 | G37: 2 | H37: =E37 -> 357 | I37: =G37*H37 -> 714 | J37: =F37-G37 -> 170
A38: 29 | B38: عين بقرة | C38: ='شهر ماي'!J2083 | E38: 1904 | F38: =C38+D38 | H38: =E38 -> 1904 | I38: =G38*H38 | J38: =F38-G38
A39: 30 | B39: زبيب جاف | C39: ='شهر ماي'!J2084 | E39: 1190 | F39: =C39+D39 | H39: =E39 -> 1190 | I39: =G39*H39 | J39: =F39-G39
A40: 31 | B40: توابل | C40: ='شهر ماي'!J2085 -> 0.95 | E40: 1428 | F40: =C40+D40 -> 0.95 | G40: 0.2 | H40: =E40 -> 1428 | I40: =G40*H40 -> 285.6 | J40: =F40-G40 -> 0.75 | L40: مقرونة +جبن + سلاطة متنوعة +خبز
A41: 32 | B41: مارغــــــرين | C41: ='شهر ماي'!J2086 -> 18 | E41: 238 | F41: =C41+D41 -> 18 | G41: 1 | H41: =E41 -> 238 | I41: =G41*H41 -> 238 | J41: =F41-G41 -> 17 | L41: برتقال + ماء
...
